{"uuid": "2c86b329-6bb2-4b7e-a18d-aa54244c9672", "children": ["41c81e9e-12d3-43e2-8488-ee275a94f33b"], "befores": [{"name": "_Class__pytest_setup_method", "status": "passed", "start": 1597713058250, "stop": 1597713060596}], "afters": [{"name": "_Class__pytest_setup_method::0", "status": "broken", "statusDetails": {"message": "selenium.common.exceptions.WebDriverException: Message: An unknown server-side error occurred while processing the command. Original error: 'appPackage' option is required\n\n", "trace": "  File \"C:\\Users\\xue\\.conda\\envs\\auto_test\\lib\\site-packages\\allure_commons\\_allure.py\", line 185, in __call__\n    return self._fixture_function(*args, **kwargs)\n  File \"C:\\Users\\xue\\.conda\\envs\\auto_test\\lib\\site-packages\\_pytest\\fixtures.py\", line 932, in _teardown_yield_fixture\n    next(it)\n  File \"C:\\Users\\xue\\.conda\\envs\\auto_test\\lib\\site-packages\\_pytest\\python.py\", line 774, in xunit_setup_method_fixture\n    _call_with_optional_argument(func, method)\n  File \"C:\\Users\\xue\\.conda\\envs\\auto_test\\lib\\site-packages\\_pytest\\python.py\", line 676, in _call_with_optional_argument\n    func()\n  File \"C:\\sourceCode\\PycharmProjects\\UI_Test\\test_case\\test_app\\test_email.py\", line 22, in teardown_method\n    self._driver.reset()\n  File \"C:\\Users\\xue\\.conda\\envs\\auto_test\\lib\\site-packages\\appium\\webdriver\\extensions\\applications.py\", line 203, in reset\n    self.execute(Command.RESET)\n  File \"C:\\Users\\xue\\.conda\\envs\\auto_test\\lib\\site-packages\\selenium\\webdriver\\remote\\webdriver.py\", line 321, in execute\n    self.error_handler.check_response(response)\n  File \"C:\\Users\\xue\\.conda\\envs\\auto_test\\lib\\site-packages\\appium\\webdriver\\errorhandler.py\", line 31, in check_response\n    raise wde\n  File \"C:\\Users\\xue\\.conda\\envs\\auto_test\\lib\\site-packages\\appium\\webdriver\\errorhandler.py\", line 26, in check_response\n    super().check_response(response)\n  File \"C:\\Users\\xue\\.conda\\envs\\auto_test\\lib\\site-packages\\selenium\\webdriver\\remote\\errorhandler.py\", line 242, in check_response\n    raise exception_class(message, screen, stacktrace)\n"}, "start": 1597713065495, "stop": 1597713065590}], "start": 1597713058249, "stop": 1597713065590}